---
name: 2 Exception during usage
about: Exception during a function call from Qlik
title: ''
labels: usage exception
assignees: ''

---

**Function**
Name of the function being used.

**Describe the bug**
A clear and concise description of the bug.

**Full error message from Python**
Provide full stack trace for the error.
If using `Qlik-Py-Start` you can provide screenshots from the terminal. Make sure to go all the way up to the start of the errors.
Alternatively, you can provide the latest log files from `../qlik-py-tools/qlik-py-env/core/logs`.

**Error message in Qlik**
Provide a screenshot of the error message in Qlik.

**Expression or load script used in Qlik**
Provide a screenshot of the expression or load script where the SSE is being used in Qlik.

**Environment:**
 - OS [e.g. Windows Server, Linux]
 - Qlik Sense Enterprise/ Desktop/ Kubernetes/ QlikView
 - SSE Version

**Additional context**
Add any other context about the problem here.
